Workbook

Sheet Read me
A1: Market intelligence Dashboard - data template
A2: Update the blue cells, save, and upload the file in the dashboard
B5: How to update the dashboard
B6: 1 | C6: Oxford Economics: paste the latest download (level values) at cell A6, header row included. Market growth for every country updates automatically.
B7: 2 | C7: Raw data: one row per country, end market and application (heating, cooling, sanitary). Update the blue cells: SAM, HFC sales and growth, and the four 1-5 scores.
B8: 3 | C8: Settings: check the company name, the current year and the Oxford Economics series names. Weights and zone lines are set in the dashboard.
B9: 4 | C9: Dashboard data: nothing to type. Check that every country appears and that the check column shows no red cells.
B10: 5 | C10: Save the file (.xlsx), open the dashboard, go to 'Update the figures' and click 'Upload Excel'.
B12: How the market figures are built
B13: End markets | C13: Residential = Oxford Economics 'Residential - Total' minus 'Multi Family'. Commercial = 'Non-Residential Building - Commercial' plus healthcare (if set in Settings) plus 'Multi Family'. Each is built for New and Renovation; total = both.
B14: Market levels | C14: Shows the resulting construction work done per country, end market and year (US$ m, 2023 prices).
B15: Growth rates | C15: CAGR last 5 years = (base year / base year - 5)^(1/5) - 1. Growth this year = current year / base year - 1. CAGR next 5 years = (current year + 5 / current year)^(1/5) - 1.
B16: History | C16: The 5-year history needs the export to start 6 years before the current year (e.g. 2020 for 2026). With a shorter export it stays empty.
B17: Series names | C17: If Oxford Economics renames a series, update its name in Settings; everything else follows.
B18: Total market | C18: Construction work done for the end market (Oxford Economics, US$ m, 2023 prices). The same for each application of a country and end market.
B19: TAM | C19: Total addressable market: spend on all HVAC and sanitary applications (heating, cooling, sanitary), in EUR m. Its CAGRs follow construction growth unless you fill the optional TAM CAGR columns.
B20: SAM | C20: Serviceable addressable market: the part of the TAM within HFC's current geographical and technology reach, in EUR m. Used for market size, market share and the matrix.
B21: Renovation / new build | C21: Calculated from the New and Renovation series: renovation share of the base year and the same three growth rates for each.
B22: Qualitative scores | C22: Profitability, competitive intensity, channel access and product fit: type a whole score from 1 to 5 (5 = most favourable for HFC).
B24: Conventions
B25: Blue cells | C25: Inputs: type or paste your figures here.
B26: Green cells | C26: Formulas: do not overwrite.
B27: Percentages | C27: Type them as percentages (3.2%) or decimals (0.032). Growth rates can be negative.
B28: Rows | C28: Room for 120 rows in Raw data (for example 20 countries x 2 end markets x 3 applications). Empty rows are ignored.
B30: Market growth and total market are real Oxford Economics data. SAM, HFC figures and qualitative scores in the sample rows are illustrative, not HFC data.

Sheet Settings
A1: Settings
A2: Company, year and Oxford Economics series. Matrix weights and zone lines are set in the dashboard.
A4: Setting | B4: Value | C4: Key (used by the dashboard, do not edit) | D4: Notes
A5: General
A6: Company name | B6: HFC | C6: company | D6: Shown in column headers and labels
A7: Current year | B7: 2026 | C7: currentYear | D7: Base year = current year - 1 (sizes and sales); history = 5 years to the base year; outlook = current year + 5
A8: Currency label | B8: EUR m | C8: currency | D8: Unit of SAM and HFC sales
A9: EUR per US$ | B9: 0.92 | C9: usdEur | D9: Converts the total market (Oxford Economics, US$) to EUR to compare it with TAM in the dashboard funnel
A11: Oxford Economics series (Indicator column of the export)
A12: Residential total - new | B12: Work Done - Residential - Total - New | C12: oe.res_total_new | D12: Residential = Residential total - Multi family (new and renovation separately)
A13: Residential total - renovation | B13: Work Done - Residential - Total - Renovation | C13: oe.res_total_reno
A14: Multi family - new | B14: Work Done - Residential - Multi Family - New | C14: oe.res_mf_new | D14: Multi family is counted in Commercial
A15: Multi family - renovation | B15: Work Done - Residential - Multi Family - Renovation | C15: oe.res_mf_reno
A16: Commercial - new | B16: Work Done - Non-Residential Building - Commercial - New | C16: oe.com_new | D16: Commercial end market = Commercial + Healthcare + Multi family (commercial already includes offices, retail and hotels)
A17: Commercial - renovation | B17: Work Done - Non-Residential Building - Commercial - Renovation | C17: oe.com_reno
A18: Healthcare - new (optional) | C18: oe.health_new | D18: Optional: type the exact Indicator name from the export; it is added to Commercial. Empty = not included
A19: Healthcare - renovation (optional) | C19: oe.health_reno

Sheet Oxford Economics
A1: Oxford Economics
A2: Paste the full Oxford Economics download here, header row in row 6 (cell A6). Level values, any years.
A3: To update: select A6, paste the new export (all columns, header row included) over the old one, and delete any leftover rows below. Columns needed: Location, Indicator and one column per year. Nothing else to change.
A4: Current data: Oxecon_download_-_9_October_2026_split.xlsx
A6: Location | B6: Indicator | C6: Units | D6: Scale | E6: Measurement | F6: 2020 | G6: 2021 | H6: 2022 | I6: 2023 | J6: 2024 | K6: 2025 | L6: 2026 | M6: 2027 | N6: 2028 | O6: 2029 | P6: 2030 | Q6: 2031 | R6: 2032 | S6: 2033 | T6: 2034 | U6: Source | V6: Seasonally adjusted | W6: Base year price | X6: Base year index | Y6: Historical end | Z6: Date of last update | AA6: Source details | AB6: Additional source details | AC6: Contact email | AD6: Location code | AE6: Indicator code
A7: Austria | B7: Work Done - Non-Residential Building - Hotels - Renovation | C7: US$ | D7: Millions: 2023 prices | E7: Level values | F7: 446.55 | G7: 412.2 | H7: 393.98 | I7: 365.17 | J7: 358.09 | K7: 336.75 | L7: 356.15 | M7: 377.49 | N7: 398.9 | O7: 414.23 | P7: 432.07 | Q7: 447.11 | R7: 460.82 | S7: 472.35 | T7: 484.17 | V7: No | W7: 2023 | Y7: 2024 | Z7: 08-October-2026 | AA7: Euroconstruct / Eurostat / Oxford Economics | AB7: NA | AC7: nfearnley@oxfordeconomics.com | AD7: AUT | AE7: WDNCHO_RT$
A8: Austria | B8: Work Done - Non-Residential Building - Retail - New | C8: US$ | D8: Millions: 2023 prices | E8: Level values | F8: 3175.33 | G8: 3364.6 | H8: 2806.75 | I8: 2541.79 | J8: 2477.22 | K8: 2310.94 | L8: 2435.73 | M8: 2534.43 | N8: 2656.74 | O8: 2746.79 | P8: 2820.76 | Q8: 2882.71 | R8: 2939.6 | S8: 2990.58 | T8: 3041.43 | V8: No | W8: 2023 | Y8: 2024 | Z8: 08-October-2026 | AA8: Euroconstruct / Eurostat / Oxford Economics | AB8: NA | AC8: nfearnley@oxfordeconomics.com | AD8: AUT | AE8: WDNCRE_NT$
A9: Austria | B9: Work Done - Non-Residential Building - Retail - Renovation | C9: US$ | D9: Millions: 2023 prices | E9: Level values | F9: 1372.81 | G9: 1309.04 | H9: 1263.96 | I9: 1177.88 | J9: 1162.3 | K9: 1088.32 | L9: 1149.84 | M9: 1199.51 | N9: 1255.19 | O9: 1292.26 | P9: 1320.48 | Q9: 1342.76 | R9: 1362.61 | S9: 1379.99 | T9: 1397.76 | V9: No | W9: 2023 | Y9: 2024 | Z9: 08-October-2026 | AA9: Euroconstruct / Eurostat / Oxford Economics | AB9: NA | AC9: nfearnley@oxfordeconomics.com | AD9: AUT | AE9: WDNCRE_RT$
A10: Austria | B10: Work Done - Non-Residential Building - Offices - New | C10: US$ | D10: Millions: 2023 prices | E10: Level values | F10: 2929.16 | G10: 2899.22 | H10: 2685.23 | I10: 2503.46 | J10: 2408.19 | K10: 2246.4 | L10: 2392.59 | M10: 2487.62 | N10: 2567.07 | O10: 2632.63 | P10: 2679.86 | Q10: 2714.48 | R10: 2742.96 | S10: 2766.29 | T10: 2794.5 | V10: No | W10: 2023 | Y10: 2024 | Z10: 08-October-2026 | AA10: Euroconstruct / Eurostat / Oxford Economics | AB10: NA | AC10: nfearnley@oxfordeconomics.com | AD10: AUT | AE10: WDNCOF_NT$
A11: Austria | B11: Work Done - Residential - Total - New | C11: US$ | D11: Millions: 2023 prices | E11: Level values | F11: 19467.85 | G11: 19073.22 | H11: 18746.98 | I11: 15840.27 | J11: 13922.12 | K11: 13237.68 | L11: 12875.72 | M11: 13044.5 | N11: 13569.31 | O11: 14089.78 | P11: 14537.82 | Q11: 15001.4 | R11: 15333.69 | S11: 15600.15 | T11: 15838.75 | V11: No | W11: 2023 | Y11: 2024 | Z11: 08-October-2026 | AA11: Euroconstruct / Eurostat / Oxford Economics | AB11: NA | AC11: nfearnley@oxfordeconomics.com | AD11: AUT | AE11: WDRALL_NT$
A12: Austria | B12: Work Done - Non-Residential Building - Offices - Renovation | C12: US$ | D12: Millions: 2023 prices | E12: Level values | F12: 1258.54 | G12: 1196.28 | H12: 1157.25 | I12: 1081.48 | J12: 1069.3 | K12: 996.93 | L12: 1053.64 | M12: 1104.75 | N12: 1160.28 | O12: 1207.03 | P12: 1245.33 | Q12: 1277.89 | R12: 1306.54 | S12: 1332.73 | T12: 1361.68 | V12: No | W12: 2023 | Y12: 2024 | Z12: 08-October-2026 | AA12: Euroconstruct / Eurostat / Oxford Economics | AB12: NA | AC12: nfearnley@oxfordeconomics.com | AD12: AUT | AE12: WDNCOF_RT$
A13: Austria | B13: Work Done - Residential - Multi Family - New | C13: US$ | D13: Millions: 2023 prices | E13: Level values | F13: 13443.4 | G13: 12641.85 | H13: 12111.45 | I13: 10463.36 | J13: 9361.11 | K13: 8775.75 | L13: 8245.32 | M13: 8128.5 | N13: 8411.93 | O13: 8747.29 | P13: 9075.62 | Q13: 9418.56 | R13: 9709.49 | S13: 9939.84 | T13: 10139.95 | V13: No | W13: 2023 | Y13: 2024 | Z13: 08-October-2026 | AA13: Euroconstruct / Eurostat / Oxford Economics | AB13: NA | AC13: nfearnley@oxfordeconomics.com | AD13: AUT | AE13: WDRMUL_NT$
A14: Austria | B14: Work Done - Residential - Total - Renovation | C14: US$ | D14: Millions: 2023 prices | E14: Level values | F14: 8652.69 | G14: 8390.41 | H14: 8512.93 | I14: 8594.05 | J14: 8906.58 | K14: 8875.05 | L14: 9672.79 | M14: 10196.48 | N14: 10457.62 | O14: 10632.24 | P14: 10765.78 | Q14: 10788.73 | R14: 10858.44 | S14: 10955.43 | T14: 11101.78 | V14: No | W14: 2023 | Y14: 2024 | Z14: 08-October-2026 | AA14: Euroconstruct / Eurostat / Oxford Economics | AB14: NA | AC14: nfearnley@oxfordeconomics.com | AD14: AUT | AE14: WDRALL_RT$
A15: Austria | B15: Work Done - Non-Residential Building - Commercial - New | C15: US$ | D15: Millions: 2023 prices | E15: Level values | F15: 6656.74 | G15: 6719.45 | H15: 6165.92 | I15: 5727.03 | J15: 5512.36 | K15: 5148.52 | L15: 5468.66 | M15: 5687.15 | N15: 5931.12 | O15: 6121.09 | P15: 6261.99 | Q15: 6382.53 | R15: 6490.75 | S15: 6584.58 | T15: 6683.55 | V15: No | W15: 2023 | Y15: 2024 | Z15: 08-October-2026 | AA15: Euroconstruct / Eurostat / Oxford Economics | AB15: NA | AC15: nfearnley@oxfordeconomics.com | AD15: AUT | AE15: WDNCTT_NT$
A16: Austria | B16: Work Done - Residential - Multi Family - Renovation | C16: US$ | D16: Millions: 2023 prices | E16: Level values | F16: 5186.26 | G16: 5142.76 | H16: 5270.72 | I16: 5307.07 | J16: 5504.38 | K16: 5612.39 | L16: 6385.62 | M16: 6769.77 | N16: 6831.45 | O16: 6859 | P16: 6880.54 | Q16: 6859.57 | R16: 6851.74 | S16: 6887.68 | T16: 6971.33 | V16: No | W16: 2023 | Y16: 2024 | Z16: 08-October-2026 | AA16: Euroconstruct / Eurostat / Oxford Economics | AB16: NA | AC16: nfearnley@oxfordeconomics.com | AD16: AUT | AE16: WDRMUL_RT$
A17: Austria | B17: Work Done - Non-Residential Building - Commercial - Renovation | C17: US$ | D17: Millions: 2023 prices | E17: Level values | F17: 3077.89 | G17: 2917.53 | H17: 2815.19 | I17: 2624.53 | J17: 2589.7 | K17: 2421.99 | L17: 2559.63 | M17: 2681.75 | N17: 2814.37 | O17: 2913.52 | P17: 2997.87 | Q17: 3067.76 | R17: 3129.97 | S17: 3185.06 | T17: 3243.6 | V17: No | W17: 2023 | Y17: 2024 | Z17: 08-October-2026 | AA17: Euroconstruct / Eurostat / Oxford Economics | AB17: NA | AC17: nfearnley@oxfordeconomics.com | AD17: AUT | AE17: WDNCTT_RT$
A18: Austria | B18: Work Done - Non-Residential Building - Hotels - New | C18: US$ | D18: Millions: 2023 prices | E18: Level values | F18: 552.24 | G18: 455.63 | H18: 673.94 | I18: 681.78 | J18: 626.95 | K18: 591.18 | L18: 640.35 | M18: 665.1 | N18: 707.3 | O18: 741.67 | P18: 761.37 | Q18: 785.34 | R18: 808.19 | S18: 827.72 | T18: 847.62 | V18: No | W18: 2023 | Y18: 2024 | Z18: 08-October-2026 | AA18: Euroconstruct / Eurostat / Oxford Economics | AB18: NA | AC18: nfearnley@oxfordeconomics.com | AD18: AUT | AE18: WDNCHO_NT$
... A234: United Kingdom | B234: Work Done - Non-Residential Building - Hotels - New | C234: US$ | D234: Millions: 2023 prices | E234: Level values | F234: 11832.99 | G234: 10713.56 | H234: 9037.78 | I234: 10399.14 | J234: 7789.8 | K234: 6829.03 | L234: 6408.57 | M234: 6358.89 | N234: 6479.83 | O234: 6721.23 | P234: 6954.51 | Q234: 7156.49 | R234: 7360.93 | S234: 7550.35 | T234: 7730.31 | V234: No | W234: 2023 | Y234: 2024 | Z234: 08-October-2026 | AA234: Euroconstruct / Eurostat / Oxford Economics | AB234: NA | AC234: nfearnley@oxfordeconomics.com | AD234: GBR | AE234: WDNCHO_NT$

Sheet Raw data
A1: Raw data
A2: One row per country and end market. Blue cells are inputs; green cells are calculated from the Oxford Economics sheet.
A3: Market growth comes from Oxford Economics (green). TAM, SAM (incl. the split by application), HFC figures and scores in the sample rows are DUMMY data for testing: replace them with your own. Add countries in the empty rows.
A4: Country / end market | F4: Market (construction work done, Oxford Economics) | N4: Renovation / new build split (Oxford Economics) | U4: HFC | AA4: Qualitative scores (1-5, 5 = most favourable)
A5: Country | B5: Code | C5: End market | D5: Application | E5: Oxford Economics location | F5: ="Total market "&(Settings!$B$7-1)&" (construction, US$ m)" -> Total market 2025 (construction, US$ m) | G5: ="TAM "&(Settings!$B$7-1)&" (EUR m)" -> TAM 2025 (EUR m) | H5: ="TAM CAGR "&(Settings!$B$7-6)&"-"&(Settings!$B$7-1)&" (optional)" -> TAM CAGR 2020-2025 (optional) | I5: ="TAM CAGR "&Settings!$B$7&"-"&(Settings!$B$7+5)&" (optional)" -> TAM CAGR 2026-2031 (optional) | J5: ="SAM "&(Settings!$B$7-1)&" (EUR m)" -> SAM 2025 (EUR m) | K5: ="Market CAGR "&(Settings!$B$7-6)&"-"&(Settings!$B$7-1) -> Market CAGR 2020-2025 | L5: ="Market growth "&Settings!$B$7&"E" -> Market growth 2026E | M5: ="Market CAGR "&Settings!$B$7&"-"&(Settings!$B$7+5) -> Market CAGR 2026-2031 | N5: Renovation share of market | O5: ="Renovation CAGR "&(Settings!$B$7-6)&"-"&(Settings!$B$7-1) -> Renovation CAGR 2020-2025 | P5: ="Renovation growth "&Settings!$B$7&"E" -> Renovation growth 2026E | Q5: ="Renovation CAGR "&Settings!$B$7&"-"&(Settings!$B$7+5) -> Renovation CAGR 2026-2031 | R5: ="New build CAGR "&(Settings!$B$7-6)&"-"&(Settings!$B$7-1) -> New build CAGR 2020-2025 | S5: ="New build growth "&Settings!$B$7&"E" -> New build growth 2026E | T5: ="New build CAGR "&Settings!$B$7&"-"&(Settings!$B$7+5) -> New build CAGR 2026-2031 | U5: ="HFC sales "&(Settings!$B$7-1)&" (EUR m)" -> HFC sales 2025 (EUR m) | V5: ="HFC sales CAGR "&(Settings!$B$7-6)&"-"&(Settings!$B$7-1) -> HFC sales CAGR 2020-2025 | W5: ="HFC growth "&Settings!$B$7&" forecast" -> HFC growth 2026 forecast | X5: ="HFC BP CAGR "&Settings!$B$7&"-"&(Settings!$B$7+5) -> HFC BP CAGR 2026-2031 | Y5: ="Market share "&(Settings!$B$7-1)&" (optional)" -> Market share 2025 (optional) | Z5: ="Market share "&Settings!$B$7&" (optional)" -> Market share 2026 (optional) | AA5: Profitability | AB5: Competitive intensity | AC5: Channel access | AD5: Product fit
A6: Poland | B6: PL | C6: Residential | D6: Heating | E6: Poland | F6: =IF($A6="","",'Market levels'!I6) -> 10329.28 | G6: 184 | J6: 71 | K6: =IF($A6="","",IFERROR(('Market levels'!I6/'Market levels'!D6)^(1/5)-1,"")) -> -0.01959925 | L6: =IF($A6="","",IFERROR('Market levels'!J6/'Market levels'!I6-1,"")) -> 0.065430504 | M6: =IF($A6="","",IFERROR(('Market levels'!O6/'Market levels'!J6)^(1/5)-1,"")) -> 0.022501524 | N6: =IF($A6="","",IFERROR('Market levels'!U6/'Market levels'!I6,"")) -> 0.53258698 | O6: =IF($A6="","",IFERROR(('Market levels'!U6/'Market levels'!P6)^(1/5)-1,"")) -> 0.021115333 | P6: =IF($A6="","",IFERROR('Market levels'!V6/'Market levels'!U6-1,"")) -> 0.18585083 | Q6: =IF($A6="","",IFERROR(('Market levels'!AA6/'Market levels'!V6)^(1/5)-1,"")) -> 0.01418054 | R6: =IF($A6="","",IFERROR(('Market levels'!AG6/'Market levels'!AB6)^(1/5)-1,"")) -> -0.056234316 | S6: =IF($A6="","",IFERROR('Market levels'!AH6/'Market levels'!AG6-1,"")) -> -0.071780681 | T6: =IF($A6="","",IFERROR(('Market levels'!AM6/'Market levels'!AH6)^(1/5)-1,"")) -> 0.034150303 | U6: 4.3 | V6: 0.09 | W6: 0.085 | X6: 0.1 | AA6: 3 | AB6: 3 | AC6: 2 | AD6: 4
A7: Poland | B7: PL | C7: Residential | D7: Cooling | E7: Poland | F7: =IF($A7="","",'Market levels'!I7) -> 10329.28 | G7: 45 | J7: 11 | K7: =IF($A7="","",IFERROR(('Market levels'!I7/'Market levels'!D7)^(1/5)-1,"")) -> -0.01959925 | L7: =IF($A7="","",IFERROR('Market levels'!J7/'Market levels'!I7-1,"")) -> 0.065430504 | M7: =IF($A7="","",IFERROR(('Market levels'!O7/'Market levels'!J7)^(1/5)-1,"")) -> 0.022501524 | N7: =IF($A7="","",IFERROR('Market levels'!U7/'Market levels'!I7,"")) -> 0.53258698 | O7: =IF($A7="","",IFERROR(('Market levels'!U7/'Market levels'!P7)^(1/5)-1,"")) -> 0.021115333 | P7: =IF($A7="","",IFERROR('Market levels'!V7/'Market levels'!U7-1,"")) -> 0.18585083 | Q7: =IF($A7="","",IFERROR(('Market levels'!AA7/'Market levels'!V7)^(1/5)-1,"")) -> 0.01418054 | R7: =IF($A7="","",IFERROR(('Market levels'!AG7/'Market levels'!AB7)^(1/5)-1,"")) -> -0.056234316 | S7: =IF($A7="","",IFERROR('Market levels'!AH7/'Market levels'!AG7-1,"")) -> -0.071780681 | T7: =IF($A7="","",IFERROR(('Market levels'!AM7/'Market levels'!AH7)^(1/5)-1,"")) -> 0.034150303 | U7: 0.3 | V7: 0.105 | W7: 0.1 | X7: 0.115 | AA7: 3 | AB7: 3 | AC7: 2 | AD7: 4
A8: Poland | B8: PL | C8: Residential | D8: Sanitary | E8: Poland | F8: =IF($A8="","",'Market levels'!I8) -> 10329.28 | G8: 102 | J8: 32 | K8: =IF($A8="","",IFERROR(('Market levels'!I8/'Market levels'!D8)^(1/5)-1,"")) -> -0.01959925 | L8: =IF($A8="","",IFERROR('Market levels'!J8/'Market levels'!I8-1,"")) -> 0.065430504 | M8: =IF($A8="","",IFERROR(('Market levels'!O8/'Market levels'!J8)^(1/5)-1,"")) -> 0.022501524 | N8: =IF($A8="","",IFERROR('Market levels'!U8/'Market levels'!I8,"")) -> 0.53258698 | O8: =IF($A8="","",IFERROR(('Market levels'!U8/'Market levels'!P8)^(1/5)-1,"")) -> 0.021115333 | P8: =IF($A8="","",IFERROR('Market levels'!V8/'Market levels'!U8-1,"")) -> 0.18585083 | Q8: =IF($A8="","",IFERROR(('Market levels'!AA8/'Market levels'!V8)^(1/5)-1,"")) -> 0.01418054 | R8: =IF($A8="","",IFERROR(('Market levels'!AG8/'Market levels'!AB8)^(1/5)-1,"")) -> -0.056234316 | S8: =IF($A8="","",IFERROR('Market levels'!AH8/'Market levels'!AG8-1,"")) -> -0.071780681 | T8: =IF($A8="","",IFERROR(('Market levels'!AM8/'Market levels'!AH8)^(1/5)-1,"")) -> 0.034150303 | U8: 1.4 | V8: 0.095 | W8: 0.09 | X8: 0.105 | AA8: 3 | AB8: 3 | AC8: 2 | AD8: 4
A9: Poland | B9: PL | C9: Commercial | D9: Heating | E9: Poland | F9: =IF($A9="","",'Market levels'!I9) -> 23418.23 | G9: 418 | J9: 161 | K9: =IF($A9="","",IFERROR(('Market levels'!I9/'Market levels'!D9)^(1/5)-1,"")) -> 0.0034147205 | L9: =IF($A9="","",IFERROR('Market levels'!J9/'Market levels'!I9-1,"")) -> 0.059659078 | M9: =IF($A9="","",IFERROR(('Market levels'!O9/'Market levels'!J9)^(1/5)-1,"")) -> 0.023450834 | N9: =IF($A9="","",IFERROR('Market levels'!U9/'Market levels'!I9,"")) -> 0.32701575 | O9: =IF($A9="","",IFERROR(('Market levels'!U9/'Market levels'!P9)^(1/5)-1,"")) -> 0.0099367466 | P9: =IF($A9="","",IFERROR('Market levels'!V9/'Market levels'!U9-1,"")) -> 0.16513823 | Q9: =IF($A9="","",IFERROR(('Market levels'!AA9/'Market levels'!V9)^(1/5)-1,"")) -> 0.020491536 | R9: =IF($A9="","",IFERROR(('Market levels'!AG9/'Market levels'!AB9)^(1/5)-1,"")) -> 0.00033497892 | S9: =IF($A9="","",IFERROR('Market levels'!AH9/'Market levels'!AG9-1,"")) -> 0.008404769 | T9: =IF($A9="","",IFERROR(('Market levels'!AM9/'Market levels'!AH9)^(1/5)-1,"")) -> 0.025097426 | U9: 7.3 | V9: 0.095 | W9: 0.09 | X9: 0.105 | AA9: 3 | AB9: 3 | AC9: 2 | AD9: 4
A10: Poland | B10: PL | C10: Commercial | D10: Cooling | E10: Poland | F10: =IF($A10="","",'Market levels'!I10) -> 23418.23 | G10: 106 | J10: 26 | K10: =IF($A10="","",IFERROR(('Market levels'!I10/'Market levels'!D10)^(1/5)-1,"")) -> 0.0034147205 | L10: =IF($A10="","",IFERROR('Market levels'!J10/'Market levels'!I10-1,"")) -> 0.059659078 | M10: =IF($A10="","",IFERROR(('Market levels'!O10/'Market levels'!J10)^(1/5)-1,"")) -> 0.023450834 | N10: =IF($A10="","",IFERROR('Market levels'!U10/'Market levels'!I10,"")) -> 0.32701575 | O10: =IF($A10="","",IFERROR(('Market levels'!U10/'Market levels'!P10)^(1/5)-1,"")) -> 0.0099367466 | P10: =IF($A10="","",IFERROR('Market levels'!V10/'Market levels'!U10-1,"")) -> 0.16513823 | Q10: =IF($A10="","",IFERROR(('Market levels'!AA10/'Market levels'!V10)^(1/5)-1,"")) -> 0.020491536 | R10: =IF($A10="","",IFERROR(('Market levels'!AG10/'Market levels'!AB10)^(1/5)-1,"")) -> 0.00033497892 | S10: =IF($A10="","",IFERROR('Market levels'!AH10/'Market levels'!AG10-1,"")) -> 0.008404769 | T10: =IF($A10="","",IFERROR(('Market levels'!AM10/'Market levels'!AH10)^(1/5)-1,"")) -> 0.025097426 | U10: 0.6 | V10: 0.11 | W10: 0.105 | X10: 0.12 | AA10: 3 | AB10: 3 | AC10: 2 | AD10: 4
A11: Poland | B11: PL | C11: Commercial | D11: Sanitary | E11: Poland | F11: =IF($A11="","",'Market levels'!I11) -> 23418.23 | G11: 229 | J11: 72 | K11: =IF($A11="","",IFERROR(('Market levels'!I11/'Market levels'!D11)^(1/5)-1,"")) -> 0.0034147205 | L11: =IF($A11="","",IFERROR('Market levels'!J11/'Market levels'!I11-1,"")) -> 0.059659078 | M11: =IF($A11="","",IFERROR(('Market levels'!O11/'Market levels'!J11)^(1/5)-1,"")) -> 0.023450834 | N11: =IF($A11="","",IFERROR('Market levels'!U11/'Market levels'!I11,"")) -> 0.32701575 | O11: =IF($A11="","",IFERROR(('Market levels'!U11/'Market levels'!P11)^(1/5)-1,"")) -> 0.0099367466 | P11: =IF($A11="","",IFERROR('Market levels'!V11/'Market levels'!U11-1,"")) -> 0.16513823 | Q11: =IF($A11="","",IFERROR(('Market levels'!AA11/'Market levels'!V11)^(1/5)-1,"")) -> 0.020491536 | R11: =IF($A11="","",IFERROR(('Market levels'!AG11/'Market levels'!AB11)^(1/5)-1,"")) -> 0.00033497892 | S11: =IF($A11="","",IFERROR('Market levels'!AH11/'Market levels'!AG11-1,"")) -> 0.008404769 | T11: =IF($A11="","",IFERROR(('Market levels'!AM11/'Market levels'!AH11)^(1/5)-1,"")) -> 0.025097426 | U11: 2.5 | V11: 0.1 | W11: 0.095 | X11: 0.11 | AA11: 3 | AB11: 3 | AC11: 2 | AD11: 4
A12: Czech Republic | B12: CZ | C12: Residential | D12: Heating | E12: Czech Republic | F12: =IF($A12="","",'Market levels'!I12) -> 5836.52 | G12: 86 | J12: 38 | K12: =IF($A12="","",IFERROR(('Market levels'!I12/'Market levels'!D12)^(1/5)-1,"")) -> -0.024085118 | L12: =IF($A12="","",IFERROR('Market levels'!J12/'Market levels'!I12-1,"")) -> -0.016814814 | M12: =IF($A12="","",IFERROR(('Market levels'!O12/'Market levels'!J12)^(1/5)-1,"")) -> 0.021904353 | N12: =IF($A12="","",IFERROR('Market levels'!U12/'Market levels'!I12,"")) -> 0.32336392 | O12: =IF($A12="","",IFERROR(('Market levels'!U12/'Market levels'!P12)^(1/5)-1,"")) -> 0.031928897 | P12: =IF($A12="","",IFERROR('Market levels'!V12/'Market levels'!U12-1,"")) -> -0.094281839 | Q12: =IF($A12="","",IFERROR(('Market levels'!AA12/'Market levels'!V12)^(1/5)-1,"")) -> 0.031068519 | R12: =IF($A12="","",IFERROR(('Market levels'!AG12/'Market levels'!AB12)^(1/5)-1,"")) -> -0.04533599 | S12: =IF($A12="","",IFERROR('Market levels'!AH12/'Market levels'!AG12-1,"")) -> 0.020206624 | T12: =IF($A12="","",IFERROR(('Market levels'!AM12/'Market levels'!AH12)^(1/5)-1,"")) -> 0.01791489 | U12: 2.7 | V12: 0.06 | W12: 0.05 | X12: 0.07 | AA12: 3 | AB12: 3 | AC12: 3 | AD12: 3
A13: Czech Republic | B13: CZ | C13: Residential | D13: Cooling | E13: Czech Republic | F13: =IF($A13="","",'Market levels'!I13) -> 5836.52 | G13: 29 | J13: 8 | K13: =IF($A13="","",IFERROR(('Market levels'!I13/'Market levels'!D13)^(1/5)-1,"")) -> -0.024085118 | L13: =IF($A13="","",IFERROR('Market levels'!J13/'Market levels'!I13-1,"")) -> -0.016814814 | M13: =IF($A13="","",IFERROR(('Market levels'!O13/'Market levels'!J13)^(1/5)-1,"")) -> 0.021904353 | N13: =IF($A13="","",IFERROR('Market levels'!U13/'Market levels'!I13,"")) -> 0.32336392 | O13: =IF($A13="","",IFERROR(('Market levels'!U13/'Market levels'!P13)^(1/5)-1,"")) -> 0.031928897 | P13: =IF($A13="","",IFERROR('Market levels'!V13/'Market levels'!U13-1,"")) -> -0.094281839 | Q13: =IF($A13="","",IFERROR(('Market levels'!AA13/'Market levels'!V13)^(1/5)-1,"")) -> 0.031068519 | R13: =IF($A13="","",IFERROR(('Market levels'!AG13/'Market levels'!AB13)^(1/5)-1,"")) -> -0.04533599 | S13: =IF($A13="","",IFERROR('Market levels'!AH13/'Market levels'!AG13-1,"")) -> 0.020206624 | T13: =IF($A13="","",IFERROR(('Market levels'!AM13/'Market levels'!AH13)^(1/5)-1,"")) -> 0.01791489 | U13: 0.3 | V13: 0.075 | W13: 0.065 | X13: 0.085 | AA13: 3 | AB13: 3 | AC13: 3 | AD13: 3
A14: Czech Republic | B14: CZ | C14: Residential | D14: Sanitary | E14: Czech Republic | F14: =IF($A14="","",'Market levels'!I14) -> 5836.52 | G14: 50 | J14: 18 | K14: =IF($A14="","",IFERROR(('Market levels'!I14/'Market levels'!D14)^(1/5)-1,"")) -> -0.024085118 | L14: =IF($A14="","",IFERROR('Market levels'!J14/'Market levels'!I14-1,"")) -> -0.016814814 | M14: =IF($A14="","",IFERROR(('Market levels'!O14/'Market levels'!J14)^(1/5)-1,"")) -> 0.021904353 | N14: =IF($A14="","",IFERROR('Market levels'!U14/'Market levels'!I14,"")) -> 0.32336392 | O14: =IF($A14="","",IFERROR(('Market levels'!U14/'Market levels'!P14)^(1/5)-1,"")) -> 0.031928897 | P14: =IF($A14="","",IFERROR('Market levels'!V14/'Market levels'!U14-1,"")) -> -0.094281839 | Q14: =IF($A14="","",IFERROR(('Market levels'!AA14/'Market levels'!V14)^(1/5)-1,"")) -> 0.031068519 | R14: =IF($A14="","",IFERROR(('Market levels'!AG14/'Market levels'!AB14)^(1/5)-1,"")) -> -0.04533599 | S14: =IF($A14="","",IFERROR('Market levels'!AH14/'Market levels'!AG14-1,"")) -> 0.020206624 | T14: =IF($A14="","",IFERROR(('Market levels'!AM14/'Market levels'!AH14)^(1/5)-1,"")) -> 0.01791489 | U14: 1 | V14: 0.065 | W14: 0.055 | X14: 0.075 | AA14: 3 | AB14: 3 | AC14: 3 | AD14: 3
A15: Czech Republic | B15: CZ | C15: Commercial | D15: Heating | E15: Czech Republic | F15: =IF($A15="","",'Market levels'!I15) -> 7763.99 | G15: 118 | J15: 52 | K15: =IF($A15="","",IFERROR(('Market levels'!I15/'Market levels'!D15)^(1/5)-1,"")) -> -0.0033703452 | L15: =IF($A15="","",IFERROR('Market levels'!J15/'Market levels'!I15-1,"")) -> 0.051150246 | M15: =IF($A15="","",IFERROR(('Market levels'!O15/'Market levels'!J15)^(1/5)-1,"")) -> 0.040003554 | N15: =IF($A15="","",IFERROR('Market levels'!U15/'Market levels'!I15,"")) -> 0.31815729 | O15: =IF($A15="","",IFERROR(('Market levels'!U15/'Market levels'!P15)^(1/5)-1,"")) -> -0.0001723686 | P15: =IF($A15="","",IFERROR('Market levels'!V15/'Market levels'!U15-1,"")) -> 0.035706045 | Q15: =IF($A15="","",IFERROR(('Market levels'!AA15/'Market levels'!V15)^(1/5)-1,"")) -> 0.054159551 | R15: =IF($A15="","",IFERROR(('Market levels'!AG15/'Market levels'!AB15)^(1/5)-1,"")) -> -0.004841768 | S15: =IF($A15="","",IFERROR('Market levels'!AH15/'Market levels'!AG15-1,"")) -> 0.058356725 | T15: =IF($A15="","",IFERROR(('Market levels'!AM15/'Market levels'!AH15)^(1/5)-1,"")) -> 0.033274643 | U15: 2.5 | V15: 0.065 | W15: 0.055 | X15: 0.075 | AA15: 3 | AB15: 3 | AC15: 3 | AD15: 3
A16: Czech Republic | B16: CZ | C16: Commercial | D16: Cooling | E16: Czech Republic | F16: =IF($A16="","",'Market levels'!I16) -> 7763.99 | G16: 36 | J16: 10 | K16: =IF($A16="","",IFERROR(('Market levels'!I16/'Market levels'!D16)^(1/5)-1,"")) -> -0.0033703452 | L16: =IF($A16="","",IFERROR('Market levels'!J16/'Market levels'!I16-1,"")) -> 0.051150246 | M16: =IF($A16="","",IFERROR(('Market levels'!O16/'Market levels'!J16)^(1/5)-1,"")) -> 0.040003554 | N16: =IF($A16="","",IFERROR('Market levels'!U16/'Market levels'!I16,"")) -> 0.31815729 | O16: =IF($A16="","",IFERROR(('Market levels'!U16/'Market levels'!P16)^(1/5)-1,"")) -> -0.0001723686 | P16: =IF($A16="","",IFERROR('Market levels'!V16/'Market levels'!U16-1,"")) -> 0.035706045 | Q16: =IF($A16="","",IFERROR(('Market levels'!AA16/'Market levels'!V16)^(1/5)-1,"")) -> 0.054159551 | R16: =IF($A16="","",IFERROR(('Market levels'!AG16/'Market levels'!AB16)^(1/5)-1,"")) -> -0.004841768 | S16: =IF($A16="","",IFERROR('Market levels'!AH16/'Market levels'!AG16-1,"")) -> 0.058356725 | T16: =IF($A16="","",IFERROR(('Market levels'!AM16/'Market levels'!AH16)^(1/5)-1,"")) -> 0.033274643 | U16: 0.2 | V16: 0.08 | W16: 0.07 | X16: 0.09 | AA16: 3 | AB16: 3 | AC16: 3 | AD16: 3
A17: Czech Republic | B17: CZ | C17: Commercial | D17: Sanitary | E17: Czech Republic | F17: =IF($A17="","",'Market levels'!I17) -> 7763.99 | G17: 67 | J17: 24 | K17: =IF($A17="","",IFERROR(('Market levels'!I17/'Market levels'!D17)^(1/5)-1,"")) -> -0.0033703452 | L17: =IF($A17="","",IFERROR('Market levels'!J17/'Market levels'!I17-1,"")) -> 0.051150246 | M17: =IF($A17="","",IFERROR(('Market levels'!O17/'Market levels'!J17)^(1/5)-1,"")) -> 0.040003554 | N17: =IF($A17="","",IFERROR('Market levels'!U17/'Market levels'!I17,"")) -> 0.31815729 | O17: =IF($A17="","",IFERROR(('Market levels'!U17/'Market levels'!P17)^(1/5)-1,"")) -> -0.0001723686 | P17: =IF($A17="","",IFERROR('Market levels'!V17/'Market levels'!U17-1,"")) -> 0.035706045 | Q17: =IF($A17="","",IFERROR(('Market levels'!AA17/'Market levels'!V17)^(1/5)-1,"")) -> 0.054159551 | R17: =IF($A17="","",IFERROR(('Market levels'!AG17/'Market levels'!AB17)^(1/5)-1,"")) -> -0.004841768 | S17: =IF($A17="","",IFERROR('Market levels'!AH17/'Market levels'!AG17-1,"")) -> 0.058356725 | T17: =IF($A17="","",IFERROR(('Market levels'!AM17/'Market levels'!AH17)^(1/5)-1,"")) -> 0.033274643 | U17: 0.9 | V17: 0.07 | W17: 0.06 | X17: 0.08 | AA17: 3 | AB17: 3 | AC17: 3 | AD17: 3
... A107: Portugal | B107: PT | C107: Commercial | D107: Sanitary | E107: Portugal | F107: =IF($A107="","",'Market levels'!I107) -> 8433.78 | G107: 67 | J107: 24 | K107: =IF($A107="","",IFERROR(('Market levels'!I107/'Market levels'!D107)^(1/5)-1,"")) -> 0.037442436 | L107: =IF($A107="","",IFERROR('Market levels'!J107/'Market levels'!I107-1,"")) -> 0.084555205 | M107: =IF($A107="","",IFERROR(('Market levels'!O107/'Market levels'!J107)^(1/5)-1,"")) -> 0.027527447 | N107: =IF($A107="","",IFERROR('Market levels'!U107/'Market levels'!I107,"")) -> 0.5403781 | O107: =IF($A107="","",IFERROR(('Market levels'!U107/'Market levels'!P107)^(1/5)-1,"")) -> 0.01618174 | P107: =IF($A107="","",IFERROR('Market levels'!V107/'Market levels'!U107-1,"")) -> 0.087586644 | Q107: =IF($A107="","",IFERROR(('Market levels'!AA107/'Market levels'!V107)^(1/5)-1,"")) -> 0.031150461 | R107: =IF($A107="","",IFERROR(('Market levels'!AG107/'Market levels'!AB107)^(1/5)-1,"")) -> 0.066314316 | S107: =IF($A107="","",IFERROR('Market levels'!AH107/'Market levels'!AG107-1,"")) -> 0.080991139 | T107: =IF($A107="","",IFERROR(('Market levels'!AM107/'Market levels'!AH107)^(1/5)-1,"")) -> 0.023174829 | U107: 1.3 | V107: 0.075 | W107: 0.06 | X107: 0.06 | AA107: 3 | AB107: 3 | AC107: 3 | AD107: 4
F108: =IF($A108="","",'Market levels'!I108) | K108: =IF($A108="","",IFERROR(('Market levels'!I108/'Market levels'!D108)^(1/5)-1,"")) | L108: =IF($A108="","",IFERROR('Market levels'!J108/'Market levels'!I108-1,"")) | M108: =IF($A108="","",IFERROR(('Market levels'!O108/'Market levels'!J108)^(1/5)-1,"")) | N108: =IF($A108="","",IFERROR('Market levels'!U108/'Market levels'!I108,"")) | O108: =IF($A108="","",IFERROR(('Market levels'!U108/'Market levels'!P108)^(1/5)-1,"")) | P108: =IF($A108="","",IFERROR('Market levels'!V108/'Market levels'!U108-1,"")) | Q108: =IF($A108="","",IFERROR(('Market levels'!AA108/'Market levels'!V108)^(1/5)-1,"")) | R108: =IF($A108="","",IFERROR(('Market levels'!AG108/'Market levels'!AB108)^(1/5)-1,"")) | S108: =IF($A108="","",IFERROR('Market levels'!AH108/'Market levels'!AG108-1,"")) | T108: =IF($A108="","",IFERROR(('Market levels'!AM108/'Market levels'!AH108)^(1/5)-1,""))
F109: =IF($A109="","",'Market levels'!I109) | K109: =IF($A109="","",IFERROR(('Market levels'!I109/'Market levels'!D109)^(1/5)-1,"")) | L109: =IF($A109="","",IFERROR('Market levels'!J109/'Market levels'!I109-1,"")) | M109: =IF($A109="","",IFERROR(('Market levels'!O109/'Market levels'!J109)^(1/5)-1,"")) | N109: =IF($A109="","",IFERROR('Market levels'!U109/'Market levels'!I109,"")) | O109: =IF($A109="","",IFERROR(('Market levels'!U109/'Market levels'!P109)^(1/5)-1,"")) | P109: =IF($A109="","",IFERROR('Market levels'!V109/'Market levels'!U109-1,"")) | Q109: =IF($A109="","",IFERROR(('Market levels'!AA109/'Market levels'!V109)^(1/5)-1,"")) | R109: =IF($A109="","",IFERROR(('Market levels'!AG109/'Market levels'!AB109)^(1/5)-1,"")) | S109: =IF($A109="","",IFERROR('Market levels'!AH109/'Market levels'!AG109-1,"")) | T109: =IF($A109="","",IFERROR(('Market levels'!AM109/'Market levels'!AH109)^(1/5)-1,""))
F110: =IF($A110="","",'Market levels'!I110) | K110: =IF($A110="","",IFERROR(('Market levels'!I110/'Market levels'!D110)^(1/5)-1,"")) | L110: =IF($A110="","",IFERROR('Market levels'!J110/'Market levels'!I110-1,"")) | M110: =IF($A110="","",IFERROR(('Market levels'!O110/'Market levels'!J110)^(1/5)-1,"")) | N110: =IF($A110="","",IFERROR('Market levels'!U110/'Market levels'!I110,"")) | O110: =IF($A110="","",IFERROR(('Market levels'!U110/'Market levels'!P110)^(1/5)-1,"")) | P110: =IF($A110="","",IFERROR('Market levels'!V110/'Market levels'!U110-1,"")) | Q110: =IF($A110="","",IFERROR(('Market levels'!AA110/'Market levels'!V110)^(1/5)-1,"")) | R110: =IF($A110="","",IFERROR(('Market levels'!AG110/'Market levels'!AB110)^(1/5)-1,"")) | S110: =IF($A110="","",IFERROR('Market levels'!AH110/'Market levels'!AG110-1,"")) | T110: =IF($A110="","",IFERROR(('Market levels'!AM110/'Market levels'!AH110)^(1/5)-1,""))
F111: =IF($A111="","",'Market levels'!I111) | K111: =IF($A111="","",IFERROR(('Market levels'!I111/'Market levels'!D111)^(1/5)-1,"")) | L111: =IF($A111="","",IFERROR('Market levels'!J111/'Market levels'!I111-1,"")) | M111: =IF($A111="","",IFERROR(('Market levels'!O111/'Market levels'!J111)^(1/5)-1,"")) | N111: =IF($A111="","",IFERROR('Market levels'!U111/'Market levels'!I111,"")) | O111: =IF($A111="","",IFERROR(('Market levels'!U111/'Market levels'!P111)^(1/5)-1,"")) | P111: =IF($A111="","",IFERROR('Market levels'!V111/'Market levels'!U111-1,"")) | Q111: =IF($A111="","",IFERROR(('Market levels'!AA111/'Market levels'!V111)^(1/5)-1,"")) | R111: =IF($A111="","",IFERROR(('Market levels'!AG111/'Market levels'!AB111)^(1/5)-1,"")) | S111: =IF($A111="","",IFERROR('Market levels'!AH111/'Market levels'!AG111-1,"")) | T111: =IF($A111="","",IFERROR(('Market levels'!AM111/'Market levels'!AH111)^(1/5)-1,""))
F112: =IF($A112="","",'Market levels'!I112) | K112: =IF($A112="","",IFERROR(('Market levels'!I112/'Market levels'!D112)^(1/5)-1,"")) | L112: =IF($A112="","",IFERROR('Market levels'!J112/'Market levels'!I112-1,"")) | M112: =IF($A112="","",IFERROR(('Market levels'!O112/'Market levels'!J112)^(1/5)-1,"")) | N112: =IF($A112="","",IFERROR('Market levels'!U112/'Market levels'!I112,"")) | O112: =IF($A112="","",IFERROR(('Market levels'!U112/'Market levels'!P112)^(1/5)-1,"")) | P112: =IF($A112="","",IFERROR('Market levels'!V112/'Market levels'!U112-1,"")) | Q112: =IF($A112="","",IFERROR(('Market levels'!AA112/'Market levels'!V112)^(1/5)-1,"")) | R112: =IF($A112="","",IFERROR(('Market levels'!AG112/'Market levels'!AB112)^(1/5)-1,"")) | S112: =IF($A112="","",IFERROR('Market levels'!AH112/'Market levels'!AG112-1,"")) | T112: =IF($A112="","",IFERROR(('Market levels'!AM112/'Market levels'!AH112)^(1/5)-1,""))
F113: =IF($A113="","",'Market levels'!I113) | K113: =IF($A113="","",IFERROR(('Market levels'!I113/'Market levels'!D113)^(1/5)-1,"")) | L113: =IF($A113="","",IFERROR('Market levels'!J113/'Market levels'!I113-1,"")) | M113: =IF($A113="","",IFERROR(('Market levels'!O113/'Market levels'!J113)^(1/5)-1,"")) | N113: =IF($A113="","",IFERROR('Market levels'!U113/'Market levels'!I113,"")) | O113: =IF($A113="","",IFERROR(('Market levels'!U113/'Market levels'!P113)^(1/5)-1,"")) | P113: =IF($A113="","",IFERROR('Market levels'!V113/'Market levels'!U113-1,"")) | Q113: =IF($A113="","",IFERROR(('Market levels'!AA113/'Market levels'!V113)^(1/5)-1,"")) | R113: =IF($A113="","",IFERROR(('Market levels'!AG113/'Market levels'!AB113)^(1/5)-1,"")) | S113: =IF($A113="","",IFERROR('Market levels'!AH113/'Market levels'!AG113-1,"")) | T113: =IF($A113="","",IFERROR(('Market levels'!AM113/'Market levels'!AH113)^(1/5)-1,""))
F114: =IF($A114="","",'Market levels'!I114) | K114: =IF($A114="","",IFERROR(('Market levels'!I114/'Market levels'!D114)^(1/5)-1,"")) | L114: =IF($A114="","",IFERROR('Market levels'!J114/'Market levels'!I114-1,"")) | M114: =IF($A114="","",IFERROR(('Market levels'!O114/'Market levels'!J114)^(1/5)-1,"")) | N114: =IF($A114="","",IFERROR('Market levels'!U114/'Market levels'!I114,"")) | O114: =IF($A114="","",IFERROR(('Market levels'!U114/'Market levels'!P114)^(1/5)-1,"")) | P114: =IF($A114="","",IFERROR('Market levels'!V114/'Market levels'!U114-1,"")) | Q114: =IF($A114="","",IFERROR(('Market levels'!AA114/'Market levels'!V114)^(1/5)-1,"")) | R114: =IF($A114="","",IFERROR(('Market levels'!AG114/'Market levels'!AB114)^(1/5)-1,"")) | S114: =IF($A114="","",IFERROR('Market levels'!AH114/'Market levels'!AG114-1,"")) | T114: =IF($A114="","",IFERROR(('Market levels'!AM114/'Market levels'!AH114)^(1/5)-1,""))
F115: =IF($A115="","",'Market levels'!I115) | K115: =IF($A115="","",IFERROR(('Market levels'!I115/'Market levels'!D115)^(1/5)-1,"")) | L115: =IF($A115="","",IFERROR('Market levels'!J115/'Market levels'!I115-1,"")) | M115: =IF($A115="","",IFERROR(('Market levels'!O115/'Market levels'!J115)^(1/5)-1,"")) | N115: =IF($A115="","",IFERROR('Market levels'!U115/'Market levels'!I115,"")) | O115: =IF($A115="","",IFERROR(('Market levels'!U115/'Market levels'!P115)^(1/5)-1,"")) | P115: =IF($A115="","",IFERROR('Market levels'!V115/'Market levels'!U115-1,"")) | Q115: =IF($A115="","",IFERROR(('Market levels'!AA115/'Market levels'!V115)^(1/5)-1,"")) | R115: =IF($A115="","",IFERROR(('Market levels'!AG115/'Market levels'!AB115)^(1/5)-1,"")) | S115: =IF($A115="","",IFERROR('Market levels'!AH115/'Market levels'!AG115-1,"")) | T115: =IF($A115="","",IFERROR(('Market levels'!AM115/'Market levels'!AH115)^(1/5)-1,""))
F116: =IF($A116="","",'Market levels'!I116) | K116: =IF($A116="","",IFERROR(('Market levels'!I116/'Market levels'!D116)^(1/5)-1,"")) | L116: =IF($A116="","",IFERROR('Market levels'!J116/'Market levels'!I116-1,"")) | M116: =IF($A116="","",IFERROR(('Market levels'!O116/'Market levels'!J116)^(1/5)-1,"")) | N116: =IF($A116="","",IFERROR('Market levels'!U116/'Market levels'!I116,"")) | O116: =IF($A116="","",IFERROR(('Market levels'!U116/'Market levels'!P116)^(1/5)-1,"")) | P116: =IF($A116="","",IFERROR('Market levels'!V116/'Market levels'!U116-1,"")) | Q116: =IF($A116="","",IFERROR(('Market levels'!AA116/'Market levels'!V116)^(1/5)-1,"")) | R116: =IF($A116="","",IFERROR(('Market levels'!AG116/'Market levels'!AB116)^(1/5)-1,"")) | S116: =IF($A116="","",IFERROR('Market levels'!AH116/'Market levels'!AG116-1,"")) | T116: =IF($A116="","",IFERROR(('Market levels'!AM116/'Market levels'!AH116)^(1/5)-1,""))
F117: =IF($A117="","",'Market levels'!I117) | K117: =IF($A117="","",IFERROR(('Market levels'!I117/'Market levels'!D117)^(1/5)-1,"")) | L117: =IF($A117="","",IFERROR('Market levels'!J117/'Market levels'!I117-1,"")) | M117: =IF($A117="","",IFERROR(('Market levels'!O117/'Market levels'!J117)^(1/5)-1,"")) | N117: =IF($A117="","",IFERROR('Market levels'!U117/'Market levels'!I117,"")) | O117: =IF($A117="","",IFERROR(('Market levels'!U117/'Market levels'!P117)^(1/5)-1,"")) | P117: =IF($A117="","",IFERROR('Market levels'!V117/'Market levels'!U117-1,"")) | Q117: =IF($A117="","",IFERROR(('Market levels'!AA117/'Market levels'!V117)^(1/5)-1,"")) | R117: =IF($A117="","",IFERROR(('Market levels'!AG117/'Market levels'!AB117)^(1/5)-1,"")) | S117: =IF($A117="","",IFERROR('Market levels'!AH117/'Market levels'!AG117-1,"")) | T117: =IF($A117="","",IFERROR(('Market levels'!AM117/'Market levels'!AH117)^(1/5)-1,""))
F118: =IF($A118="","",'Market levels'!I118) | K118: =IF($A118="","",IFERROR(('Market levels'!I118/'Market levels'!D118)^(1/5)-1,"")) | L118: =IF($A118="","",IFERROR('Market levels'!J118/'Market levels'!I118-1,"")) | M118: =IF($A118="","",IFERROR(('Market levels'!O118/'Market levels'!J118)^(1/5)-1,"")) | N118: =IF($A118="","",IFERROR('Market levels'!U118/'Market levels'!I118,"")) | O118: =IF($A118="","",IFERROR(('Market levels'!U118/'Market levels'!P118)^(1/5)-1,"")) | P118: =IF($A118="","",IFERROR('Market levels'!V118/'Market levels'!U118-1,"")) | Q118: =IF($A118="","",IFERROR(('Market levels'!AA118/'Market levels'!V118)^(1/5)-1,"")) | R118: =IF($A118="","",IFERROR(('Market levels'!AG118/'Market levels'!AB118)^(1/5)-1,"")) | S118: =IF($A118="","",IFERROR('Market levels'!AH118/'Market levels'!AG118-1,"")) | T118: =IF($A118="","",IFERROR(('Market levels'!AM118/'Market levels'!AH118)^(1/5)-1,""))
F119: =IF($A119="","",'Market levels'!I119) | K119: =IF($A119="","",IFERROR(('Market levels'!I119/'Market levels'!D119)^(1/5)-1,"")) | L119: =IF($A119="","",IFERROR('Market levels'!J119/'Market levels'!I119-1,"")) | M119: =IF($A119="","",IFERROR(('Market levels'!O119/'Market levels'!J119)^(1/5)-1,"")) | N119: =IF($A119="","",IFERROR('Market levels'!U119/'Market levels'!I119,"")) | O119: =IF($A119="","",IFERROR(('Market levels'!U119/'Market levels'!P119)^(1/5)-1,"")) | P119: =IF($A119="","",IFERROR('Market levels'!V119/'Market levels'!U119-1,"")) | Q119: =IF($A119="","",IFERROR(('Market levels'!AA119/'Market levels'!V119)^(1/5)-1,"")) | R119: =IF($A119="","",IFERROR(('Market levels'!AG119/'Market levels'!AB119)^(1/5)-1,"")) | S119: =IF($A119="","",IFERROR('Market levels'!AH119/'Market levels'!AG119-1,"")) | T119: =IF($A119="","",IFERROR(('Market levels'!AM119/'Market levels'!AH119)^(1/5)-1,""))
... F125: =IF($A125="","",'Market levels'!I125) | K125: =IF($A125="","",IFERROR(('Market levels'!I125/'Market levels'!D125)^(1/5)-1,"")) | L125: =IF($A125="","",IFERROR('Market levels'!J125/'Market levels'!I125-1,"")) | M125: =IF($A125="","",IFERROR(('Market levels'!O125/'Market levels'!J125)^(1/5)-1,"")) | N125: =IF($A125="","",IFERROR('Market levels'!U125/'Market levels'!I125,"")) | O125: =IF($A125="","",IFERROR(('Market levels'!U125/'Market levels'!P125)^(1/5)-1,"")) | P125: =IF($A125="","",IFERROR('Market levels'!V125/'Market levels'!U125-1,"")) | Q125: =IF($A125="","",IFERROR(('Market levels'!AA125/'Market levels'!V125)^(1/5)-1,"")) | R125: =IF($A125="","",IFERROR(('Market levels'!AG125/'Market levels'!AB125)^(1/5)-1,"")) | S125: =IF($A125="","",IFERROR('Market levels'!AH125/'Market levels'!AG125-1,"")) | T125: =IF($A125="","",IFERROR(('Market levels'!AM125/'Market levels'!AH125)^(1/5)-1,""))

Sheet Market levels
A1: Market levels
A2: Construction work done per country and end market (US$ m, 2023 prices), calculated from the Oxford Economics sheet. Do not type here.
A3: Residential = Residential total - Multi family. Commercial = Commercial + Healthcare (if set) + Multi family. Each for renovation and new build; total = both. Empty = year or series not in the export.
D4: Total (renovation + new build) | P4: Renovation | AB4: New build
A5: Country | B5: End market | C5: Oxford Economics location | D5: =Settings!$B$7-6 -> 2020 | E5: =Settings!$B$7-5 -> 2021 | F5: =Settings!$B$7-4 -> 2022 | G5: =Settings!$B$7-3 -> 2023 | H5: =Settings!$B$7-2 -> 2024 | I5: =Settings!$B$7-1 -> 2025 | J5: =Settings!$B$7 -> 2026 | K5: =Settings!$B$7+1 -> 2027 | L5: =Settings!$B$7+2 -> 2028 | M5: =Settings!$B$7+3 -> 2029 | N5: =Settings!$B$7+4 -> 2030 | O5: =Settings!$B$7+5 -> 2031 | P5: =Settings!$B$7-6 -> 2020 | Q5: =Settings!$B$7-5 -> 2021 | R5: =Settings!$B$7-4 -> 2022 | S5: =Settings!$B$7-3 -> 2023 | T5: =Settings!$B$7-2 -> 2024 | U5: =Settings!$B$7-1 -> 2025 | V5: =Settings!$B$7 -> 2026 | W5: =Settings!$B$7+1 -> 2027 | X5: =Settings!$B$7+2 -> 2028 | Y5: =Settings!$B$7+3 -> 2029 | Z5: =Settings!$B$7+4 -> 2030 | AA5: =Settings!$B$7+5 -> 2031 | AB5: =Settings!$B$7-6 -> 2020 | AC5: =Settings!$B$7-5 -> 2021 | AD5: =Settings!$B$7-4 -> 2022 | AE5: =Settings!$B$7-3 -> 2023 | AF5: =Settings!$B$7-2 -> 2024 | AG5: =Settings!$B$7-1 -> 2025 | AH5: =Settings!$B$7 -> 2026 | AI5: =Settings!$B$7+1 -> 2027 | AJ5: =Settings!$B$7+2 -> 2028 | AK5: =Settings!$B$7+3 -> 2029 | AL5: =Settings!$B$7+4 -> 2030 | AM5: =Settings!$B$7+5 -> 2031
